[{"items": [{"tags": ["machine-learning", "tensorflow", "deep-learning", "python-3.5"], "owner": {"user_type": "does_not_exist", "display_name": "user5368329"}, "is_answered": false, "view_count": 214, "answer_count": 0, "score": 1, "last_activity_date": 1505214434, "creation_date": 1505213884, "last_edit_date": 1505214434, "question_id": 46174656, "content_license": "CC BY-SA 3.0", "link": "https://stackoverflow.com/questions/46174656/tensorflow-core", "title": "Tensorflow core", "body": "<p>I run the code below on Tensorflow 1.0 using python 3.5</p>\n\n<pre><code>a = tf.placeholder(tf.float32)\nb = tf.placeholder(tf.float32)\nadder_node = a + b  # + provides a shortcut for tf.add(a, b)\nsess = tf.Session()\nprint(sess.run(adder_node, {a: 3, b: 4.5}))\nprint(sess.run(adder_node, {a: [1, 3], b: [2, 4]}))\n</code></pre>\n\n<p>I got this error</p>\n\n<blockquote>\n  <blockquote>\n    <blockquote>\n      <p>print(sess.run(adder_node, {a:3, b:4.5}))\n      Traceback (most recent call last):\n        File \"C:\\Users\\xxxx\\AppData\\Local\\Continuum\\Anaconda3\\envs\\tensorflow\\lib\\site-packages\\tensorflow\\python\\client\\session.py\", line 1068, in _run\n          allow_operation=False)\n        File \"C:\\Users\\xxxx\\AppData\\Local\\Continuum\\Anaconda3\\envs\\tensorflow\\lib\\site-packages\\tensorflow\\python\\framework\\ops.py\", line 2708, in as_graph_element\n          return self._as_graph_element_locked(obj, allow_tensor, allow_operation)\n        File \"C:\\Users\\xxxx\\AppData\\Local\\Continuum\\Anaconda3\\envs\\tensorflow\\lib\\site-packages\\tensorflow\\python\\framework\\ops.py\", line 2787, in _as_graph_element_locked\n          raise ValueError(\"Tensor %s is not an element of this graph.\" % obj)\n      ValueError: Tensor Tensor(\"Placeholder_3:0\", dtype=float32) is not an element of this graph.</p>\n    </blockquote>\n  </blockquote>\n</blockquote>\n\n<p>During handling of the above exception, another exception occurred:</p>\n\n<p>Traceback (most recent call last):\n  File \"\", line 1, in \n  File \"C:\\Users\\xxxx\\AppData\\Local\\Continuum\\Anaconda3\\envs\\tensorflow\\lib\\site-packages\\tensorflow\\python\\client\\session.py\", line 895, in run\n    run_metadata_ptr)\n  File \"C:\\Users\\xxxx\\AppData\\Local\\Continuum\\Anaconda3\\envs\\tensorflow\\lib\\site-packages\\tensorflow\\python\\client\\session.py\", line 1071, in _run\n    + e.args[0])\nTypeError: Cannot interpret feed_dict key as Tensor: Tensor Tensor(\"Placeholder_3:0\", dtype=float32) is not an element of this graph.</p>\n\n<blockquote>\n  <blockquote>\n    <p>></p>\n  </blockquote>\n</blockquote>\n\n<p>Please help me debug this, not too sure where the error is coming from</p>\n"}], "has_more": false, "quota_max": 300, "quota_remaining": 97}]