[{"items": [{"tags": ["python", "tensorflow", "neural-network", "deep-learning"], "owner": {"user_type": "does_not_exist", "display_name": "user7671217"}, "is_answered": true, "view_count": 2924, "accepted_answer_id": 50930634, "answer_count": 1, "score": 1, "last_activity_date": 1529898578, "creation_date": 1529416938, "last_edit_date": 1529898578, "question_id": 50930376, "content_license": "CC BY-SA 4.0", "link": "https://stackoverflow.com/questions/50930376/tensorflow-valueerror-none-values-not-supported", "title": "TensorFlow :ValueError: None values not supported", "body": "<pre><code>import tensorflow as tf\nimport matplotlib.pyplot as plt\n\nfrom tensorflow.examples.tutorials.mnist import input_data\n\nmnist=input_data.read_data_sets('MNIST_DATA/',one_hot=True)\ndef init_weights(shape):\n    init_random_dist=tf.truncated_normal(shape,stddev=0.1)\n\n    return tf.Variable(init_random_dist)\ndef init_bias(shape):\n    init_bias_vals=tf.constant(0.1,shape=shape)\n    return tf.Variable(init_bias_vals)\ndef conv2d(x,W):\n\n    return tf.nn.conv2d(x,W,strides=[1,1,1,1],padding='SAME')\ndef max_pool_2by2(x):\n    tf.nn.max_pool(x,ksize=[1,2,2,1],strides=[1,2,2,1],padding='SAME')\ndef conv(input_x,shape):\n    W=init_weights(shape)\n    b=init_bias([shape[3]])\n    return tf.nn.relu(conv2d(input_x,W)+b )\ndef normal(input_layer,size):\n    input_size=int(input_layer.get_shape()[1])\n    W=init_weights([input_size,size])\n    b=init_bias([size])\n    return tf.matmul(input_layer,W)+b\nx=tf.placeholder(tf.float32,shape=[None,784])\ny_true=tf.placeholder(tf.float32,shape=[None,10])\nx_image=tf.reshape(x,[-1,28,28,1])\n\n conv1=conv(x_image,shape=[5,5,1,32])\n conv1_pooling=max_pool_2by2(conv1)\n# # conv2=conv(conv1_pooling,shape=[5,5,32,64])\n conv2=conv(conv1_pooling,shape=[5,5,32,64])\n conv2_pooling=max_pool_2by2(conv2)\n conv2_flat=tf.reshape(conv2_pooling,[-1,7*7*64])\n full_layer=tf.nn.relu(normal(conv2_flat,1024))\n</code></pre>\n\n<p>but when i tried to run this code i ran in to a strange error </p>\n\n<pre><code>ValueError: None values not supported.\n\nDuring handling of the above exception, another exception occurred:\n</code></pre>\n\n<p>all those code was learn't from a tutorial but when i tried to run the jupyter notebook of that tutorial the code executed well and there was no issue or error after execution \ni dont know the reason why my code is popping up with an error </p>\n\n<p>any kind of help is appreciated \nEDIT1: i didnt run this code in tensorflow session \nfollowing the tutorial the tutor told  to  run this code in order to check any kind of issues </p>\n"}], "has_more": false, "quota_max": 300, "quota_remaining": 281}]