[{"items": [{"tags": ["tensorflow", "tensorflow-lite"], "owner": {"account_id": 10523211, "reputation": 3, "user_id": 7754989, "user_type": "registered", "accept_rate": 50, "profile_image": "https://graph.facebook.com/427258234291276/picture?type=large", "display_name": "Sree Lakshmi", "link": "https://stackoverflow.com/users/7754989/sree-lakshmi"}, "is_answered": false, "view_count": 163, "answer_count": 1, "score": 0, "last_activity_date": 1574189745, "creation_date": 1574079828, "question_id": 58914513, "content_license": "CC BY-SA 4.0", "link": "https://stackoverflow.com/questions/58914513/error-while-converting-a-frozen-pb-file-to-tflite-format", "title": "Error while converting a frozen.pb file to tflite format", "body": "<pre><code>tflite_convert   --output_file=./graph.tflite   --graph_def_file=output_graph_frozen.pb   --input_arrays=IteratorV2 --output_arrays=linear/head/predictions/probabilities\n</code></pre>\n\n<p>Traceback (most recent call last):\n  File \"/usr/local/bin/tflite_convert\", line 11, in \n    sys.exit(main())\n  File \"/usr/local/lib/python3.6/dist-packages/tensorflow/lite/python/tflite_convert.py\", line 503, in main\n    app.run(main=run_main, argv=sys.argv[:1])\n  File \"/usr/local/lib/python3.6/dist-packages/tensorflow/python/platform/app.py\", line 40, in run\n    _run(main=main, argv=argv, flags_parser=_parse_flags_tolerate_undef)\n  File \"/usr/local/lib/python3.6/dist-packages/absl/app.py\", line 299, in run\n    _run_main(main, args)\n  File \"/usr/local/lib/python3.6/dist-packages/absl/app.py\", line 250, in _run_main\n    sys.exit(main(argv))\n  File \"/usr/local/lib/python3.6/dist-packages/tensorflow/lite/python/tflite_convert.py\", line 499, in run_main\n    _convert_tf1_model(tflite_flags)\n  File \"/usr/local/lib/python3.6/dist-packages/tensorflow/lite/python/tflite_convert.py\", line 193, in _convert_tf1_model\n    output_data = converter.convert()\n  File \"/usr/local/lib/python3.6/dist-packages/tensorflow/lite/python/lite.py\", line 898, in convert\n    **converter_kwargs)\n  File \"/usr/local/lib/python3.6/dist-packages/tensorflow/lite/python/convert.py\", line 401, in toco_convert_impl\n    input_tensors, output_tensors, *args, **kwargs)\n  File \"/usr/local/lib/python3.6/dist-packages/tensorflow/lite/python/convert.py\", line 304, in build_toco_convert_protos\n    input_tensor.dtype)\n  File \"/usr/local/lib/python3.6/dist-packages/tensorflow/lite/python/util.py\", line 58, in convert_dtype_to_tflite_type\n    raise ValueError(\"Unsupported tf.dtype {0}\".format(tf_dtype))\nValueError: Unsupported tf.dtype </p>\n"}], "has_more": false, "quota_max": 300, "quota_remaining": 53}]