[{"items": [{"tags": ["tensorflow"], "owner": {"account_id": 2811841, "reputation": 872, "user_id": 2417922, "user_type": "registered", "accept_rate": 0, "profile_image": "https://www.gravatar.com/avatar/5cee40c36bc502473b0976b339a8b8da?s=256&d=identicon&r=PG", "display_name": "Mark Lavin", "link": "https://stackoverflow.com/users/2417922/mark-lavin"}, "is_answered": false, "view_count": 64, "answer_count": 1, "score": 1, "last_activity_date": 1623966729, "creation_date": 1623936433, "last_edit_date": 1623957018, "question_id": 68020370, "content_license": "CC BY-SA 4.0", "link": "https://stackoverflow.com/questions/68020370/why-is-tensorflow-save-model-failing", "title": "Why is Tensorflow &quot;save_model&quot; failing?", "body": "<p>I'm working in Tensorflow 2.0.0, and trying to save a  model.  Here's the code I'm using (thanks to @m-innat for suggesting to simplify the\nexample model)</p>\n<pre><code>class SimpleModel( tf.keras.Model ):\n    def __init__( self, **kwargs ):\n        super( SimpleModel, self ).__init__( **kwargs )\n        self.conv = tf.keras.layers.Conv1D( filters = 5, kernel_size = 3, padding = &quot;SAME&quot; )\n        self.dense = tf.keras.layers.Dense( 1 )\n    def call( self, x ):\n        x = self.conv( x )\n        x = self.dense( x )\n        return x\n\nsimple_model = SimpleModel()\n\ninput_shape = ( 3, 4, 5 )\nx = tf.random.normal( shape = input_shape )\ny = tf.random.normal( shape = ( 3, 4, 1 ) )\ny_pred = simple_model( x )\nprint( &quot;y_pred&quot;, y_pred )\n\ntf.keras.models.save_model( translation_model, \n    &quot;/content/gdrive/MyDrive/SimpleModel.tf&quot;, save_format = &quot;tf&quot; )\n</code></pre>\n<p>However, the <code>save_model</code> call gives an error:</p>\n<pre><code>AttributeError: 'NoneType' object has no attribute 'shape'\n</code></pre>\n<p>Nothing in the call stack suggests what the underlying problem is.  Can you please help?</p>\n"}], "has_more": false, "quota_max": 300, "quota_remaining": 122}]